Workbook
Name DF_GRID_1: #REF!
Name DF_GRID_2: #REF!
Name DF_GRID_3: #REF!
Name DF_GRID_4: #REF!
Name DF_GRID_5: #REF!
Name JR_PAGE_ANCHOR_0_1: #REF!
Name а: #REF!
Name Бюджет: #REF!
Name в: #REF!
Name ГАБСэкономия: #REF!
Name дф: #REF!
Name желтая: #REF!
Name инд2019: #REF!
Name индекс2017: #REF!
Name индекс2018: #REF!
Name индекс2020: #REF!
Name индекс2021: #REF!
Name мосты: #REF!
Name мосты2: #REF!
Name МУН: #REF!
Name ноль: #REF!
Name объекты: #REF!
Name объекты12.07.19: #REF!
Name объекты2019: #REF!
Name ооо: #REF!
Name про: #REF!
Name ррр: #REF!
Name трнкрн: #REF!
Name фы: #REF!

Sheet СВОД СМР
W1: тыс. руб.
C3: № | D3: Подрядчики | E3: Заключено ГК на сумму | F3: Кол-во объектов/ контрактов | G3: Средняя стоимость контракта | H3: Оплачено на 01.01.2026 | I3: Процент оплаты | J3: Аванс по ГК | K3: % аванса по ГК | L3: Выданный аванс всего | M3: % выданного аванса | N3: Неотработанный аванс | O3: % неотработанного аванаса | P3: Оплачено всего | Q3: % оплаты | R3: Выполнено всего | S3: % выполнения | T3: Лимит 2026 было | U3: Лимит 2026 текущий | V3: Лимит 2027 было | W3: Лимит 2027 текущий
E4: =SUM(E5:E32) -> 2.4110774e+08 | F4: =SUM(F5:F32) -> 104 | J4: =SUM(J5:J32) -> 92630820 | K4: =J4/E4 -> 0.38418849 | L4: =SUM(L5:L32) -> 74879145 | M4: =L4/J4 -> 0.80836103 | N4: =SUM(N5:N32) -> 44838965 | O4: =N4/L4 -> 0.59881781 | P4: =SUM(P5:P32) -> 1.1796629e+08 | Q4: =P4/E4 -> 0.48926795 | R4: =SUM(R5:R32) -> 73314369 | S4: =R4/E4 -> 0.30407306 | T4: =SUM(T5:T32) -> 17919910 | U4: =SUM(U5:U32) -> 28197121 | V4: =SUM(V5:V32) -> 25312808 | W4: =SUM(W5:W32) -> 28593994
B5: =#REF!-#REF!-#REF!-#REF! -> #REF! | C5: 1 | D5: СТГ | E5: ='контракты СМР'!D4 -> 61044205 | F5: 14 | J5: ='контракты СМР'!F4 -> 29414196 | K5: =J5/E5 -> 0.48185076 | L5: ='контракты СМР'!H4 -> 26798060 | M5: 0.90077157 | N5: ='контракты СМР'!K4 -> 15244604 | O5: 0.59561567 | P5: ='контракты СМР'!M4 -> 37836048 | Q5: 0.61548819 | R5: ='контракты СМР'!O4 -> 22591444 | S5: 0.36733126 | T5: ='контракты СМР'!S4 -> 1767022.6 | U5: ='контракты СМР'!V4 -> 5655417.6 | V5: ='контракты СМР'!AA4 -> 4026813.6 | W5: ='контракты СМР'!AB4 -> 5016070.6
C6: 2 | D6: АРКС+МИСК | E6: ='контракты СМР'!D41+'контракты СМР'!D49 -> 57138138 | F6: 16 | J6: ='контракты СМР'!F49+'контракты СМР'!F41 -> 22719415 | K6: =J6/E6 -> 0.3976226 | L6: ='контракты СМР'!H41+'контракты СМР'!H49 -> 20823360 | M6: 0.82 | N6: ='контракты СМР'!K41+'контракты СМР'!K49 -> 14644634 | O6: 0.65 | P6: ='контракты СМР'!M41+'контракты СМР'!M49 -> 30857232 | Q6: 0.5 | R6: ='контракты СМР'!O41+'контракты СМР'!O49 -> 16212598 | S6: 0.29 | T6: ='контракты СМР'!S41+'контракты СМР'!S49 -> 2531762.1 | U6: ='контракты СМР'!V41+'контракты СМР'!V49 -> 6221164.9 | V6: ='контракты СМР'!AA41+'контракты СМР'!AA49 -> 1655774.1 | W6: ='контракты СМР'!AB41+'контракты СМР'!AB49 -> 4195861.7
B7: =#REF!-#REF!-#REF!-#REF! -> #REF! | C7: 3 | D7: ДИМ | E7: ='контракты СМР'!D19 -> 28155094 | F7: 7 | J7: ='контракты СМР'!F19 -> 11521893 | K7: =J7/E7 -> 0.40922941 | L7: ='контракты СМР'!H19 -> 7241237.3 | M7: =L7/J7 -> 0.62847638 | N7: ='контракты СМР'!K19 -> 3353747.4 | O7: =N7/L7 -> 0.46314562 | P7: ='контракты СМР'!M19 -> 10043966 | Q7: =P7/E7 -> 0.35673708 | R7: ='контракты СМР'!O19 -> 6690218.7 | S7: =R7/E7 -> 0.23762018 | T7: ='контракты СМР'!S19 -> 1208300.2 | U7: ='контракты СМР'!V19 -> 4518278.9 | V7: ='контракты СМР'!AA19 -> 1999150.4 | W7: ='контракты СМР'!AB19 -> 701982.45
B8: =#REF!-#REF!-#REF!-#REF! -> #REF! | C8: 4 | D8: ВИС | E8: ='контракты СМР'!D59 -> 21008610 | F8: 5 | J8: ='контракты СМР'!F59 -> 5430575.1 | K8: =J8/E8 -> 0.25849283 | L8: ='контракты СМР'!H59 -> 4966757 | M8: 0.71798305 | N8: ='контракты СМР'!K59 -> 4590067 | O8: 0.92364906 | P8: ='контракты СМР'!M59 -> 5227494.5 | Q8: 0.24192331 | R8: ='контракты СМР'!O59 -> 634328.91 | S8: 0.029543135 | T8: ='контракты СМР'!S59 -> 1213622.1 | U8: ='контракты СМР'!V59 -> 1616592.3 | V8: ='контракты СМР'!AA59 -> 1284331.5 | W8: ='контракты СМР'!AB59 -> 2041839.8
B9: =#REF!-#REF!-#REF!-#REF! -> #REF! | C9: 5 | D9: Сибагро | E9: ='контракты СМР'!D34 -> 18443317 | F9: 3 | J9: ='контракты СМР'!F34 -> 6085839.2 | K9: =J9/E9 -> 0.32997531 | L9: ='контракты СМР'!H34 -> 4898579.6 | M9: 0.90841533 | N9: ='контракты СМР'!K34 -> 282294.54 | O9: 0.098553039 | P9: ='контракты СМР'!M34 -> 17825341 | Q9: 0.96320184 | R9: ='контракты СМР'!O34 -> 17543900 | S9: 0.93777299 | T9: ='контракты СМР'!S34 -> 567665.18 | U9: ='контракты СМР'!V34 -> 601465.95 | V9: ='контракты СМР'!AA34 -> 0 | W9: ='контракты СМР'!AB34 -> 0
B10: =#REF!-#REF!-#REF!-#REF! -> #REF! | C10: 6 | D10: МСУ | E10: ='контракты СМР'!D66 -> 11014191 | F10: 8 | J10: ='контракты СМР'!F66 -> 3935402.2 | K10: =J10/E10 -> 0.35730289 | L10: ='контракты СМР'!H66 -> 2298714.5 | M10: 0.75176854 | N10: ='контракты СМР'!K66 -> 1940771.2 | O10: 1 | P10: ='контракты СМР'!M66 -> 1940771.2 | Q10: 0.1568977 | R10: ='контракты СМР'!O66 -> 0 | S10: 0 | T10: ='контракты СМР'!S66 -> 817629.38 | U10: ='контракты СМР'!V66 -> 1052629.4 | V10: ='контракты СМР'!AA66 -> 2088023.6 | W10: ='контракты СМР'!AB66 -> 1648023.6
B11: =#REF!-#REF!-#REF!-#REF! -> #REF! | C11: 7 | D11: Орион | E11: ='контракты СМР'!D111 -> 7283697.7 | F11: 3 | J11: ='контракты СМР'!F111 -> 934465.5 | K11: =J11/E11 -> 0.12829548 | L11: ='контракты СМР'!H111 -> 118232.85 | M11: 0.048172465 | N11: ='контракты СМР'!K111 -> 118232.85 | O11: 1 | P11: ='контракты СМР'!M111 -> 118232.85 | Q11: 0.0061803096 | R11: ='контракты СМР'!O111 -> 0 | S11: 0 | T11: ='контракты СМР'!S111 -> 1496211.3 | U11: ='контракты СМР'!V111 -> 2034560.6 | V11: ='контракты СМР'!AA111 -> 5523664.1 | W11: ='контракты СМР'!AB111 -> 5067170.6
B12: =#REF!-#REF!-#REF!-#REF! -> #REF! | C12: 8 | D12: Роуд Групп | E12: ='контракты СМР'!D27 -> 5882577.9 | F12: 6 | J12: ='контракты СМР'!F27 -> 2245038.3 | K12: =J12/E12 -> 0.38164191 | L12: ='контракты СМР'!H27 -> 1138170.2 | M12: =L12/J12 -> 0.50697142 | N12: ='контракты СМР'!K27 -> 384563.52 | O12: =N12/L12 -> 0.33787874 | P12: ='контракты СМР'!M27 -> 2256412.5 | Q12: =P12/E12 -> 0.38357546 | R12: ='контракты СМР'!O27 -> 2010302.3 | S12: =R12/E12 -> 0.34173833 | T12: ='контракты СМР'!S27 -> 246305.23 | U12: ='контракты СМР'!V27 -> 1173496.4 | V12: ='контракты СМР'!AA27 -> 1043005.5 | W12: ='контракты СМР'!AB27 -> 1509448.3
B13: =#REF!-#REF!-#REF!-#REF! -> #REF! | C13: 9 | D13: ЕКС | E13: ='контракты СМР'!D99 -> 4325702.8 | F13: 2 | J13: ='контракты СМР'!F99 -> 1297710.9 | K13: =J13/E13 -> 0.3 | L13: ='контракты СМР'!H99 -> 69561.057 | M13: 0.053602894 | N13: ='контракты СМР'!K99 -> 109311.05 | O13: 1 | P13: ='контракты СМР'!M99 -> 109311.05 | Q13: 0.016080868 | R13: ='контракты СМР'!O99 -> 0 | S13: 0 | T13: ='контракты СМР'!S99 -> 1176000.3 | U13: ='контракты СМР'!V99 -> 277309.13 | V13: ='контракты СМР'!AA99 -> 1959813.1 | W13: ='контракты СМР'!AB99 -> 1084792.2
B14: =#REF!-#REF!-#REF!-#REF! -> #REF! | C14: 10 | D14: Стройком | E14: ='контракты СМР'!D37 -> 3951124.7 | F14: 2 | J14: ='контракты СМР'!F37 -> 1185337.4 | K14: =J14/E14 -> 0.3 | L14: ='контракты СМР'!H37 -> 1175636.8 | M14: 0.99198913 | N14: ='контракты СМР'!K37 -> 40039.59 | O14: 0.03405185 | P14: ='контракты СМР'!M37 -> 3903059.9 | Q14: 0.97248866 | R14: ='контракты СМР'!O37 -> 3903059.9 | S14: 0.95827439 | T14: ='контракты СМР'!S37 -> 51076.039 | U14: ='контракты СМР'!V37 -> 108700.75 | V14: ='контракты СМР'!AA37 -> 0 | W14: ='контракты СМР'!AB37 -> 0
B15: =#REF!-#REF!-#REF!-#REF! -> #REF! | C15: 11 | D15: Руслан-1 | E15: ='контракты СМР'!D75 -> 3941898.9 | F15: 4 | J15: ='контракты СМР'!F75 -> 1564261.8 | K15: =J15/E15 -> 0.3968295 | L15: ='контракты СМР'!H75 -> 847503.11 | M15: 0.25593753 | N15: ='контракты СМР'!K75 -> 715667.16 | O15: 0.86091345 | P15: ='контракты СМР'!M75 -> 1152588.4 | Q15: 0.19364743 | R15: ='контракты СМР'!O75 -> 436921.23 | S15: 0.07224967 | T15: ='контракты СМР'!S75 -> 1346519.2 | U15: ='контракты СМР'!V75 -> 1063046.5 | V15: ='контракты СМР'!AA75 -> 1679515.7 | W15: ='контракты СМР'!AB75 -> 1417490.4
B16: =#REF!-#REF!-#REF!-#REF! -> #REF! | C16: 12 | D16: Энергия Ом | E16: ='контракты СМР'!D121 -> 3523860.8 | F16: 2 | J16: ='контракты СМР'!F121 -> 1506496.2 | K16: =J16/E16 -> 0.42751298 | L16: ='контракты СМР'!H121 -> 1506496.2 | M16: 1 | N16: ='контракты СМР'!K121 -> 1167290.2 | O16: 0.82859127 | P16: ='контракты СМР'!M121 -> 2297977.1 | Q16: 0.62997059 | R16: ='контракты СМР'!O121 -> 1130686.9 | S16: 0.27573707 | T16: ='контракты СМР'!S121 -> 1233345 | U16: ='контракты СМР'!V121 -> 266475.13 | V16: ='контракты СМР'!AA121 -> 0 | W16: ='контракты СМР'!AB121 -> 1037457
B17: =#REF!-#REF!-#REF!-#REF! -> #REF! | C17: 13 | D17: Мостэнергострой | E17: ='контракты СМР'!D127 -> 3210785.6 | F17: 3 | J17: ='контракты СМР'!F127 -> 530085.5 | K17: =J17/E17 -> 0.16509527 | L17: ='контракты СМР'!H127 -> 530085.5 | M17: =L17/J17 -> 1 | N17: ='контракты СМР'!K127 -> 530085.5 | O17: =N17/L17 -> 1 | P17: ='контракты СМР'!M127 -> 530085.5 | Q17: =P17/E17 -> 0.16509527 | R17: ='контракты СМР'!O127 -> 0 | S17: =R17/E17 -> 0 | T17: ='контракты СМР'!S127 -> 1504762.8 | U17: ='контракты СМР'!V127 -> 1081569.6 | V17: ='контракты СМР'!AA127 -> 1434611.8 | W17: ='контракты СМР'!AB127 -> 1857805
B18: =#REF!-#REF!-#REF!-#REF! -> #REF! | C18: 14 | D18: Белый Раст | E18: ='контракты СМР'!D80 -> 2758579.7 | F18: 7 | J18: ='контракты СМР'!F80 -> 943598.32 | K18: =J18/E18 -> 0.34205947 | L18: ='контракты СМР'!H80 -> 477240.54 | M18: 0.55120653 | N18: ='контракты СМР'!K80 -> 271447.51 | O18: 0.74792709 | P18: ='контракты СМР'!M80 -> 899233.41 | Q18: 0.26166779 | R18: ='контракты СМР'!O80 -> 627785.9 | S18: 0.14707185 | T18: ='контракты СМР'!S80 -> 518393.73 | U18: ='контракты СМР'!V80 -> 750761.35 | V18: ='контракты СМР'!AA80 -> 1252645.9 | W18: ='контракты СМР'!AB80 -> 802725.89
B19: =#REF!-#REF!-#REF!-#REF! -> #REF! | C19: 15 | D19: Магистраль | E19: ='контракты СМР'!D105 -> 2464867.7 | F19: 5 | J19: ='контракты СМР'!F105 -> 738575.32 | K19: =J19/E19 -> 0.29964096 | L19: ='контракты СМР'!H105 -> 353064.49 | M19: 0.26612516 | N19: ='контракты СМР'!K105 -> 291525.88 | O19: 0.92572251 | P19: ='контракты СМР'!M105 -> 514788.78 | Q19: 0.093542275 | R19: ='контракты СМР'!O105 -> 223262.91 | S19: 0.019739203 | T19: ='контракты СМР'!S105 -> 278608.06 | U19: ='контракты СМР'!V105 -> 454711.57 | V19: ='контракты СМР'!AA105 -> 364387.28 | W19: ='контракты СМР'!AB105 -> 573157.45
B20: =#REF!-#REF!-#REF!-#REF! -> #REF! | C20: 16 | D20: Автобан | E20: ='контракты СМР'!D124 -> 1909798.3 | F20: 2 | J20: ='контракты СМР'!F124 -> 572939.5 | K20: =J20/E20 -> 0.3 | L20: ='контракты СМР'!H124 -> 559828.49 | M20: 0.97711623 | N20: ='контракты СМР'!K124 -> 520000 | O20: 0.92885591 | P20: ='контракты СМР'!M124 -> 638651.91 | Q20: 0.33440804 | R20: ='контракты СМР'!O124 -> 118651.91 | S20: 0.062127978 | T20: ='контракты СМР'!S124 -> 37000 | U20: ='контракты СМР'!V124 -> 25000 | V20: ='контракты СМР'!AA124 -> 90000 | W20: ='контракты СМР'!AB124 -> 90000
B21: =#REF!-#REF!-#REF!-#REF! -> #REF! | C21: 17 | D21: Забдорстрой | E21: ='контракты СМР'!D102 -> 780267.05 | F21: 3 | J21: ='контракты СМР'!F102 -> 292322.36 | K21: =J21/E21 -> 0.37464398 | L21: ='контракты СМР'!H102 -> 210605.6 | M21: 0.77937784 | N21: ='контракты СМР'!K102 -> 136750.56 | O21: 0.78927061 | P21: ='контракты СМР'!M102 -> 273176.26 | Q21: 0.33241137 | R21: ='контракты СМР'!O102 -> 136425.7 | S21: 0.12884915 | T21: ='контракты СМР'!S102 -> 151485.56 | U21: ='контракты СМР'!V102 -> 225521.29 | V21: ='контракты СМР'!AA102 -> 193074.45 | W21: ='контракты СМР'!AB102 -> 80000
B22: =#REF!-#REF!-#REF!-#REF! -> #REF! | C22: 18 | D22: Инжиниринг Групп | E22: ='контракты СМР'!D97 -> 788938.2 | F22: 1 | J22: ='контракты СМР'!F97 -> 556090.38 | K22: =J22/E22 -> 0.70485924 | L22: ='контракты СМР'!H97 -> 22000.005 | M22: 0.039561923 | N22: ='контракты СМР'!K97 -> 22000.005 | O22: 1 | P22: ='контракты СМР'!M97 -> 22000.005 | Q22: 0.019780962 | R22: ='контракты СМР'!O97 -> 0 | S22: 0 | T22: ='контракты СМР'!S97 -> 530000 | U22: ='контракты СМР'!V97 -> 77450.194 | V22: ='контракты СМР'!AA97 -> 538180.76 | W22: ='контракты СМР'!AB97 -> 689488.01
B23: =#REF!-#REF!-#REF!-#REF! -> #REF! | C23: 19 | D23: Барстт | E23: ='контракты СМР'!D88 -> 653212.29 | F23: 2 | J23: ='контракты СМР'!F88 -> 95527.699 | K23: =J23/E23 -> 0.14624296 | L23: ='контракты СМР'!H88 -> 95527.7 | M23: 1 | N23: ='контракты СМР'!K88 -> 62763.383 | O23: 0.65701763 | P23: ='контракты СМР'!M88 -> 183344.26 | Q23: 0.28068097 | R23: ='контракты СМР'!O88 -> 120580.87 | S23: 0.18459676 | T23: ='контракты СМР'!S88 -> 383887.89 | U23: ='контракты СМР'!V88 -> 184048.87 | V23: ='контракты СМР'!AA88 -> 0 | W23: ='контракты СМР'!AB88 -> 285819.16
B24: =#REF!-#REF!-#REF!-#REF! -> #REF! | C24: 20 | D24: Силич | E24: ='контракты СМР'!D91 -> 526938.58 | F24: 1 | J24: ='контракты СМР'!F91 -> 247661.13 | K24: =J24/E24 -> 0.47 | L24: ='контракты СМР'!H91 -> 246866.75 | M24: 0.99679247 | N24: ='контракты СМР'!K91 -> 76549.001 | O24: 0.31008226 | P24: ='контракты СМР'!M91 -> 449875.03 | Q24: 0.85375232 | R24: ='контракты СМР'!O91 -> 373326.03 | S24: 0.70848111 | T24: ='контракты СМР'!S91 -> 77063.546 | U24: ='контракты СМР'!V91 -> 77063.546 | V24: ='контракты СМР'!AA91 -> 0 | W24: ='контракты СМР'!AB91 -> 0
B25: =#REF!-#REF!-#REF!-#REF! -> #REF! | C25: 21 | D25: Антарес С | E25: ='контракты СМР'!D93 -> 522435.25 | F25: 1 | J25: ='контракты СМР'!F93 -> 156730.58 | K25: =J25/E25 -> 0.3 | L25: ='контракты СМР'!H93 -> 156730.58 | M25: 0.47096753 | N25: ='контракты СМР'!K93 -> 126425.81 | O25: 0.83553677 | P25: ='контракты СМР'!M93 -> 225300.35 | Q25: 0.19141128 | R25: ='контракты СМР'!O93 -> 98847.542 | S25: 0.073358073 | T25: ='контракты СМР'!S93 -> 422435.25 | U25: ='контракты СМР'!V93 -> 272938.79 | V25: ='контракты СМР'!AA93 -> 0 | W25: ='контракты СМР'!AB93 -> 149496.46
B26: =#REF!-#REF!-#REF!-#REF! -> #REF! | C26: 22 | D26: Строй НЭС АБ | E26: ='контракты СМР'!D117 -> 358961.55 | F26: 1 | J26: ='контракты СМР'!F117 -> 110286.32 | K26: ='контракты СМР'!G117 -> 0.3 | L26: ='контракты СМР'!H117 -> 110286.32 | M26: 1.0241238 | N26: ='контракты СМР'!K117 -> 29939.288 | O26: 0.27146875 | P26: ='контракты СМР'!M117 -> 288514.14 | Q26: 0.80374664 | R26: ='контракты СМР'!O117 -> 258574.85 | S26: 0.72034135 | T26: ='контракты СМР'!S117 -> 63483.887 | U26: ='контракты СМР'!V117 -> 70447.412 | V26: ='контракты СМР'!AA117 -> 0 | W26: ='контракты СМР'!AB117 -> 0
B27: =#REF!-#REF!-#REF!-#REF! -> #REF! | C27: 23 | D27: Еврострой | E27: ='контракты СМР'!D95 -> 274979.45 | F27: 1 | J27: ='контракты СМР'!F95 -> 137489.72 | K27: =J27/E27 -> 0.5 | L27: ='контракты СМР'!H95 -> 7581.544 | M27: 0.055142624 | N27: ='контракты СМР'!K95 -> 7581.544 | O27: 1 | P27: ='контракты СМР'!M95 -> 7581.544 | Q27: 0.027571312 | R27: ='контракты СМР'!O95 -> 0 | S27: 0 | T27: ='контракты СМР'!S95 -> 87581.544 | U27: ='контракты СМР'!V95 -> 71581.544 | V27: ='контракты СМР'!AA95 -> 179816.36 | W27: ='контракты СМР'!AB95 -> 195816.36
B28: =#REF!-#REF!-#REF!-#REF! -> #REF! | C28: 24 | D28: Пелискер | E28: ='контракты СМР'!D119 -> 223239.46 | F28: 1 | J28: ='контракты СМР'!F119 -> 111767.8 | K28: =J28/E28 -> 0.50066328 | L28: ='контракты СМР'!H119 -> 108880.62 | M28: 0.97416803 | N28: ='контракты СМР'!K119 -> 108880.62 | O28: 1 | P28: ='контракты СМР'!M119 -> 118636.62 | Q28: 0.48773016 | R28: ='контракты СМР'!O119 -> 19808.131 | S28: 0 | T28: ='контракты СМР'!S119 -> 94805.289 | U28: ='контракты СМР'!V119 -> 114358.84 | V28: ='контракты СМР'!AA119 -> 0 | W28: ='контракты СМР'!AB119 -> 0
B29: =#REF!-#REF!-#REF!-#REF! -> #REF! | C29: 25 | D29: Автобаза Ильинское | E29: ='контракты СМР'!D115 -> 188607.68 | F29: 1 | J29: ='контракты СМР'!F115 -> 54344.158 | K29: =J29/E29 -> 0.28813332 | L29: ='контракты СМР'!H115 -> 54344.158 | M29: =L29/J29 -> 1 | N29: ='контракты СМР'!K115 -> 0 | O29: =N29/L29 -> 0 | P29: ='контракты СМР'!M115 -> 182870.79 | Q29: =P29/E29 -> 0.96958295 | R29: ='контракты СМР'!O115 -> 183645.59 | S29: =R29/E29 -> 0.97369093 | T29: ='контракты СМР'!S115 -> 114943.61 | U29: ='контракты СМР'!V115 -> 109985.86 | V29: ='контракты СМР'!AA115 -> 0 | W29: ='контракты СМР'!AB116 -> 4957.755
B30: =#REF!-#REF!-#REF!-#REF! -> #REF! | C30: 26 | D30: РТС | E30: ='контракты СМР'!D131 -> 24080.922 | F30: 1 | G30: 1 | H30: 1 | I30: 1 | J30: ='контракты СМР'!F131 -> 12044.461 | K30: =J30/E30 -> 0.50016611 | L30: ='контракты СМР'!H131 -> 12040.461 | M30: =L30/J30 -> 0.9996679 | N30: ='контракты СМР'!K131 -> 12040.461 | O30: =N30/L30 -> 1 | P30: ='контракты СМР'!M131 -> 12044.461 | Q30: =P30/E30 -> 0.50016611 | R30: ='контракты СМР'!O131 -> 0 | S30: =R30/E30 -> 0 | U30: ='контракты СМР'!V131 -> 24080.922 | W30: ='контракты СМР'!AB131 -> 0
C31: 27 | D31: Автодороги | E31: ='контракты СМР'!D133 -> 620448.09 | F31: 1 | G31: 1 | H31: 1 | I31: 1 | J31: ='контракты СМР'!F133 -> 186134.43 | K31: =J31/E31 -> 0.3 | L31: ='контракты СМР'!H133 -> 7161.5879 | M31: =L31/J31 -> 0.038475354 | N31: ='контракты СМР'!K133 -> 7161.5879 | O31: =N31/L31 -> 1 | P31: ='контракты СМР'!M133 -> 7161.5879 | Q31: =P31/E31 -> 0.011542606 | R31: ='контракты СМР'!O133 -> 0 | S31: =R31/E31 -> 0 | U31: ='контракты СМР'!V133 -> 23871.96 | W31: ='контракты СМР'!AB133 -> 100000
B32: =#REF!-#REF!-#REF!-#REF! -> #REF! | C32: 28 | D32: ВТМ Дорпроект | E32: ='контракты СМР'!D135 -> 89183.073 | F32: 1 | G32: 1 | H32: 1 | I32: 1 | J32: ='контракты СМР'!F135 -> 44591.536 | K32: =J32/E32 -> 0.5 | L32: ='контракты СМР'!H135 -> 44591.536 | M32: =L32/J32 -> 1 | N32: ='контракты СМР'!K135 -> 44591.536 | O32: 0 | P32: ='контракты СМР'!M135 -> 44591.536 | Q32: =P32/E32 -> 0.5 | R32: ='контракты СМР'!O135 -> 0 | S32: =R32/E32 -> 0 | U32: ='контракты СМР'!V135 -> 44591.536 | W32: ='контракты СМР'!AB135 -> 44591.536
B33: =#REF!-#REF!-#REF!-#REF! -> #REF!
B34: =#REF!-#REF!-#REF!-#REF! -> #REF!
B35: =#REF!-#REF!-#REF!-#REF! -> #REF!
B36: =#REF!-#REF!-#REF!-#REF! -> #REF!
B37: =#REF!-#REF!-#REF!-#REF! -> #REF!
B38: =#REF!-#REF!-#REF!-#REF! -> #REF!
B39: =#REF!-#REF!-#REF!-#REF! -> #REF!
B40: =#REF!-#REF!-#REF!-#REF! -> #REF!
B41: =#REF!-#REF!-#REF!-#REF! -> #REF!
...

Sheet контракты СМР
A1: № п/п | C1: Контракт № | D1: Стоимость ГК | E1: ВР | F1: Аванс по ГК | G1: % аванса по ГК | H1: Выданный Аванс | I1: % выдан-го аванса | J1: Выданный аванс за 2025 | K1: Неотраб-ый аванс | L1: % нетработ-ого аванса | M1: Оплачено ВСЕГО | N1: % оплаты | O1: Выполнено ВСЕГО | P1: % вып-ния | Q1: Выполнено в 2025 | R1: Оплачено в 2025 | S1: Лимит 2026 было | T1: Лимит ВСЕГО по объекту 2026 | U1: лимит изъятия 2026 | V1: лимит контракта СМР 2026 текущий | W1: секвс-ние 2026 | X1: Оплачено 2026 | Y1: в т.ч. Аванс | Z1: Остаток финан-ния на 2026 | AA1: Лимит 2027 было | AB1: Лимит контракта 2027 текущий | AC1: Лимит объекта 2027 | AD1: Лимит контракта 2028 текущий | AE1: Лимит объекта 2028 | AF1: Лимит контракта 2029 текущий | AG1: Лимит объекта 2029 | AH1: % СГ | AI1: % изъятия | AJ1: ППТ | AK1: Плановый срок ввода по ГП | AL1: Плановый срок открытия | AM1: Срок контракта
B2: ВСЕГО | D2: =D4+D19+D27+D34+D37+D41+D49+D59+D66+D75+D80+D88+D91+D93+D95+D97+D99+D102+D105+D111+D115+D117+D119+D121+D124+D127 -> 2.4037403e+08 | F2: =F4+F19+F27+F34+F37+F41+F49+F59+F66+F75+F80+F88+F91+F93+F95+F97+F99+F102+F105+F111+F115+F117+F119+F121+F124+F127 -> 92388050 | G2: =F2/D2 -> 0.38435121 | H2: =H4+H19+H27+H34+H37+H41+H49+H59+H66+H75+H80+H88+H91+H93+H95+H97+H99+H102+H105+H111+H115+H117+H119+H121+H124+H127 -> 74815352 | I2: =H2/F2 -> 0.80979469 | J2: =J4+J19+J27+J34+J37+J41+J49+J59+J66+J75+J80+J88+J91+J93+J95+J97+J99+J102+J105+J111+J115+J117+J119+J121+J124+J127 -> 27202711 | K2: =K4+K19+K27+K34+K37+K41+K49+K59+K66+K75+K80+K88+K91+K93+K95+K97+K99+K102+K105+K111+K115+K117+K119+K121+K124+K127 -> 44775172 | L2: =K2/H2 -> 0.59847573 | M2: =M4+M19+M27+M34+M37+M41+M49+M59+M66+M75+M80+M88+M91+M93+M95+M97+M99+M102+M105+M111+M115+M117+M119+M121+M124+M127 -> 1.1790249e+08 | N2: =M2/D2 -> 0.49049597 | O2: =O4+O19+O27+O34+O37+O41+O49+O59+O66+O75+O80+O88+O91+O93+O95+O97+O99+O102+O105+O111+O115+O117+O119+O121+O124+O127 -> 73314369 | P2: =O2/D2 -> 0.30500121 | Q2: =Q4+Q19+Q27+Q34+Q37+Q41+Q49+Q59+Q66+Q75+Q80+Q88+Q91+Q93+Q95+Q97+Q99+Q102+Q105+Q111+Q115+Q117+Q119+Q121+Q124+Q127 -> 23095411 | R2: =R4+R19+R27+R34+R37+R41+R49+R59+R66+R75+R80+R88+R91+R93+R95+R97+R99+R102+R105+R111+R115+R117+R119+R121+R124+R127 -> 35539295 | S2: =S4+S19+S27+S34+S37+S41+S49+S59+S66+S75+S80+S88+S91+S93+S95+S97+S99+S102+S105+S111+S115+S117+S119+S121+S124+S127 -> 17919910 | T2: =T4+T19+T27+T34+T37+T41+T49+T59+T66+T75+T80+T88+T91+T93+T95+T97+T99+T102+T105+T111+T115+T117+T119+T121+T124+T127 -> 36142151 | U2: =U4+U19+U27+U34+U37+U41+U49+U59+U66+U75+U80+U88+U91+U93+U95+U97+U99+U102+U105+U111+U115+U117+U119+U121+U124+U127 -> 1838877.1 | V2: =V4+V19+V27+V34+V37+V41+V49+V59+V66+V75+V80+V88+V91+V93+V95+V97+V99+V102+V105+V111+V115+V117+V119+V121+V124+V127 -> 28104576 | W2: =W4+W19+W27+W34+W37+W41+W49+W59+W66+W75+W80+W88+W91+W93+W95+W97+W99+W102+W105+W111+W115+W117+W119+W121+W124+W127 -> 4608000 | X2: =X4+X19+X27+X34+X37+X41+X49+X59+X66+X75+X80+X88+X91+X93+X95+X97+X99+X102+X105+X111+X115+X117+X119+X121+X124+X127 -> 8077446.2 | ... AG2: =AG4+AG19+AG27+AG34+AG37+AG41+AG49+AG59+AG66+AG75+AG80+AG88+AG91+AG93+AG95+AG97+AG99+AG102+AG105+AG111+AG115+AG117+AG119+AG121+AG124+AG127 -> 65537536
B4: СТГ | D4: =SUM(D5:D18) -> 61044205 | F4: =SUM(F5:F18) -> 29414196 | G4: =F4/D4 -> 0.48185076 | H4: =SUM(H5:H18) -> 26798060 | I4: =H4/F4 -> 0.91105873 | J4: =SUM(J5:J18) -> 7986047.3 | K4: =SUM(K5:K18) -> 15244604 | L4: =K4/H4 -> 0.5688697 | M4: =SUM(M5:M18) -> 37836048 | N4: =M4/D4 -> 0.61981392 | O4: =SUM(O5:O18) -> 22591444 | P4: =O4/D4 -> 0.37008335 | Q4: =SUM(Q5:Q18) -> 4116915.7 | R4: =SUM(R5:R18) -> 9308624.8 | S4: =SUM(S12:S18) -> 1767022.6 | T4: =SUM(T5:T18) -> 6978461 | U4: =SUM(U5:U18) -> 222139.46 | V4: =SUM(V5:V18) -> 5655417.6 | W4: =SUM(W5:W18) -> 1631000 | X4: =SUM(X5:X18) -> 0 | Y4: =SUM(Y5:Y18) -> 0 | Z4: =SUM(Z5:Z18) -> 5655417.6 | AA4: =SUM(AA12:AA18) -> 4026813.6 | AB4: =SUM(AB5:AB18) -> 5016070.6 | AC4: =SUM(AC5:AC18) -> 7789056 | AD4: =SUM(AD5:AD18) -> 9865694.6 | AE4: =SUM(AE5:AE18) -> 13405777 | AF4: =SUM(AF5:AF18) -> 2670974 | AG4: =SUM(AG5:AG18) -> 7190395.9
A5: 1 | B5: Строительство автомобильной дороги МКАД - аэропорт Домодедово - Коробово в Ленинском городском округе Московской области | C5: 46289 | D5: 2197700.2 | E5: СМР+ПИР | F5: 697849.43 | G5: =F5/D5 -> 0.31753622 | H5: 692477.6 | I5: =H5/F5 -> 0.99230231 | J5: 0 | K5: 651260.97 | L5: =K5/H5 -> 0.94047947 | M5: 777894.38 | N5: =M5/D5 -> 0.35395837 | O5: 126633.41 | P5: =O5/D5 -> 0.057620877 | Q5: 126633.41 | R5: 85416.783 | S5: 98000 | T5: 253000 | V5: 250000 | Z5: =V5-X5 -> 250000 | AA5: 1252805.8 | AB5: 250000 | AC5: 280000 | AD5: 919805.84 | AE5: 1467255.4 | AG5: 67000 | AH5: 0.01 | AI5: 1 | AJ5: да | AK5: 47114 | AL5: 46557 | AM5: 46783 | AN5: =D5-M5-Z5-AB5-AD5-AF5 -> 0.0009499999
A6: 2 | B6: Опалиха | C6: 25-95 | D6: 1704671.5 | E6: СМР | F6: 852335.72 | G6: =F6/D6 -> 0.5 | H6: 569565.68 | I6: =H6/F6 -> 0.668241 | J6: 569565.68 | K6: 569565.68 | L6: =K6/H6 -> 1 | M6: 569565.68 | N6: =M6/D6 -> 0.3341205 | O6: 0 | P6: =O6/D6 -> 0 | Q6: 0 | R6: 569565.68 | S6: 1153563.8 | T6: 1154172.7 | V6: 1135105.8 | Z6: =V6-X6 -> 1135105.8 | AA6: 0 | AC6: 204000 | AH6: 0.4 | AI6: 1 | AJ6: да | AK6: 46752 | AL6: 46356 | AM6: 46405 | AN6: =D6-M6-Z6-AB6-AD6-AF6 -> -0.00015000021
A7: 3 | B7: Апрелевка | C7: 25-127 | D7: 3312365.1 | E7: СМР+ПИР | F7: 1656182.6 | G7: =F7/D7 -> 0.5 | H7: 861244.23 | I7: =H7/F7 -> 0.52001769 | J7: 861244.23 | K7: 861244.23 | L7: =K7/H7 -> 1 | M7: 861244.23 | N7: =M7/D7 -> 0.26000885 | O7: 0 | P7: =O7/D7 -> 0 | Q7: 0 | R7: 861244.23 | S7: 1929582.3 | T7: 2112884.3 | U7: 7053.08 | V7: 1969243.8 | Z7: =V7-X7 -> 1969243.8 | AA7: 0 | AB7: 481877.07 | AC7: 493498.05 | AH7: 0.45 | AI7: 0.97 | AJ7: да | AK7: 46752 | AL7: 46356 | AM7: 46492 | AN7: =D7-M7-Z7-AB7-AD7-AF7 -> -0.00031999976
A8: 4 | B8: Реконструкция Каширского шоссе на участке км 0- км 4,4 в Ленинском районе | C8: 22-52 | D8: 19683924 | E8: СМР+ПИР | F8: 10641056 | G8: =F8/D8 -> 0.5405963 | H8: 10557472 | I8: =H8/F8 -> 0.99214509 | J8: 5859350.9 | K8: 9025483.4 | L8: =K8/H8 -> 0.8548906 | M8: =12893597.40074-600000 -> 12293597 | N8: =M8/D8 -> 0.62455015 | O8: 3268114 | P8: =O8/D8 -> 0.1660296 | Q8: 2900772.6 | R8: 6634819 | S8: 847116.61 | T8: 905382.74 | V8: =250000+47116.61206 -> 297116.61 | Z8: =V8-X8 -> 297116.61 | AA8: 550000 | AB8: 400000 | AC8: 1827282 | AD8: 5500000 | AE8: 7107430.8 | AF8: 1193209.6 | AG8: 2898778.1 | AH8: 0.47 | AI8: 0.95 | AJ8: да | AK8: 47479 | AL8: 45049 | AM8: 46783 | AN8: =D8-M8-Z8-AB8-AD8-AF8 -> 0.00027000206
A9: 5 | B9: Реконструкция Октябрьского проспекта в г.Люберцы на участке граница г.Москвы-Егорьевское шоссе. 1 этап. От ул. Власова до путепровода через ж/д | C9: 19-14 | D9: 5268439.8 | E9: СМР | F9: 3687907.8 | G9: =F9/D9 -> 0.7 | H9: 3687907.8 | I9: =H9/F9 -> 1 | J9: 0 | K9: 1290259.7 | L9: =K9/H9 -> 0.34986223 | M9: 4840476.6 | N9: =M9/D9 -> 0.91876853 | O9: 3550217 | P9: =O9/D9 -> 0.67386497 | Q9: 175525.59 | R9: 43489.273 | S9: 372452.4 | T9: 429471.84 | V9: 427963.13 | W9: 184000 | Z9: =V9-X9 -> 427963.13 | AA9: 0 | AC9: 372000 | AH9: 0.91 | AI9: 1 | AJ9: да | AK9: 46748 | AL9: 45176 | AM9: 46112 | AN9: =D9-M9-Z9-AB9-AD9-AF9 -> -0.00032000028
A10: 6 | B10: Реконструкция автомобильной дороги «Лобня-аэропорт Шереметьево» | C10: 19-111 | D10: 4600055.4 | E10: СМР | F10: 2300027.7 | G10: =F10/D10 -> 0.5 | H10: 2500000 | I10: =H10/F10 -> 1.0869434 | J10: 236888.43 | K10: 659826.81 | L10: =K10/H10 -> 0.26393073 | M10: 4090706.2 | N10: =M10/D10 -> 0.88927325 | O10: 3430879.4 | P10: =O10/D10 -> 0.74583437 | Q10: 464795.38 | R10: 464702.32 | S10: 343051.48 | T10: 307359.81 | V10: 269933 | Z10: =V10-X10 -> 269933 | AA10: 0 | AB10: 239416.16 | AC10: 250000 | AE10: 16 | AH10: 0.97 | AI10: 1 | AJ10: да | AK10: 47114 | AL10: 44925 | AM10: 46052 | AN10: =D10-M10-Z10-AB10-AD10-AF10 -> 0.00024000034
A11: 7 | B11: Реконструкция автомобильной дороги г.Жуковский, ул.Туполева | C11: Ф.2018.322600 | D11: 7955408.6 | E11: СМР | F11: 4664989.5 | G11: =F11/D11 -> 0.58639219 | H11: 4664989.5 | I11: =H11/F11 -> 1 | J11: 0 | K11: 458746.29 | L11: =K11/H11 -> 0.09833812 | M11: 7677586.3 | N11: =M11/D11 -> 0.96507756 | O11: 7218840 | P11: =O11/D11 -> 0.90741286 | Q11: 405053.62 | R11: 148897.71 | S11: 196719.96 | T11: 285775.41 | V11: 277822.25 | Z11: =V11-X11 -> 277822.25 | AA11: 0 | AC11: 41000 | AH11: 0.98 | AI11: 1 | AJ11: да | AK11: 46748 | AL11: 44916 | AM11: 46112 | AN11: =D11-M11-Z11-AB11-AD11-AF11 -> -4.0745363e-10
A12: 8 | B12: Строительство автомобильной дороги на участке Рублевский проезд - «Новый выход на МКАД с федеральной автомобильной дороги М-1 «Беларусь» Москва - Минск» | C12: 19-19 | D12: 2526555.6 | E12: СМР | F12: 731439.61 | G12: =F12/D12 -> 0.2895007 | H12: 731439.61 | I12: =H12/F12 -> 1 | J12: 0 | K12: 35399.647 | L12: =K12/H12 -> 0.048397224 | M12: 2153709.1 | N12: =M12/D12 -> 0.85242896 | O12: 2118309.5 | P12: =O12/D12 -> 0.83841792 | Q12: 0 | R12: 0 | S12: 364096.44 | T12: 100000 | V12: 98711.06 | Z12: =V12-X12 -> 98711.06 | AA12: 0 | AB12: 274135.39 | AC12: 274135.39 | AH12: движение запущено | AI12: 1 | AJ12: да | AK12: 46748 | AL12: 44195 | AM12: 46053 | AN12: =D12-M12-Z12-AB12-AD12-AF12 -> 0.00050000002
A13: 9 | B13: Строительство транспортной развязки на пересечении автомобильной дороги М-10 «Россия» и улицы Репина в городе Химки Московской области | C13: 19-110 | D13: 2800488 | E13: СМР | F13: 840146.39 | G13: =F13/D13 -> 0.3 | H13: 840146.39 | I13: =H13/F13 -> 1 | J13: 0 | K13: 0 | L13: =K13/H13 -> 0 | M13: 2585570.3 | N13: =M13/D13 -> 0.92325705 | O13: 2585570.3 | P13: =O13/D13 -> 0.92325705 | Q13: 44135.062 | R13: 41491.784 | S13: 214707.34 | T13: 218958.67 | V13: 214917.7 | Z13: =V13-X13 -> 214917.7 | AA13: 0 | AB13: 0 | AH13: движение запущено | AI13: 1 | AJ13: да | AK13: 47848 | AL13: 44218 | AM13: 46053 | AN13: =D13-M13-Z13-AB13-AD13-AF13 -> 0.00012000007
A14: 10 | B14: Строительство участка автомобильной дороги регионального значения «Молоковское шоссе – Нижнее Мячково» в Ленинском городском округе Московской области | C14: 22-73 | D14: 4779285.2 | E14: СМР+ПИР | F14: 1345921.5 | G14: =F14/D14 -> 0.28161564 | H14: 1208640.5 | I14: =H14/F14 -> 0.89800223 | J14: 0 | K14: 1208640.5 | L14: =K14/H14 -> 1 | M14: 1501520.7 | N14: =M14/D14 -> 0.31417266 | O14: 292880.26 | P14: =O14/D14 -> 0.061281184 | Q14: 0 | R14: 0 | S14: 71000 | T14: 324253.55 | U14: 215086.38 | V14: 100000 | W14: 300000 | Z14: =V14-X14 -> 100000 | AA14: 980000 | AB14: 260000 | AC14: 277390.61 | AD14: 1440000 | AE14: 1500000 | AF14: 1477764.4 | AG14: 4224617.8 | AH14: идет проект-ние | AI14: 0.95 | AJ14: да | AK14: 47479 | AL14: 46446 | AM14: 46811 | AN14: =D14-M14-Z14-AB14-AD14-AF14 -> -3.9999839e-05
A15: 11 | B15: Строительство участка автомобильной дороги Щербинка - Федюково - Каширское шоссе (1 этап) и подъезда к ж\д станции Калинина в Ленинском городском округе Московской области | C15: 24-54 | D15: 1033849.2 | E15: СМР+ПИР | F15: 310154.76 | G15: =F15/D15 -> 0.3 | H15: 13968.121 | I15: =H15/F15 -> 0.045035972 | J15: 0 | K15: 13968.121 | L15: =K15/H15 -> 1 | M15: 13968.122 | N15: =M15/D15 -> 0.013510793 | O15: 0 | P15: =O15/D15 -> 0 | Q15: 0 | R15: 0 | S15: 26624.162 | T15: 137592.29 | V15: 104992.28 | Z15: =V15-X15 -> 104992.28 | AA15: 70000 | AB15: 72000 | AC15: 78000 | AD15: 842888.79 | AE15: 1170439.6 | AH15: идет проект-ние | AK15: 47114 | AL15: 46831 | AM15: 46831 | AN15: =D15-M15-Z15-AB15-AD15-AF15 -> -0.0001399999
A16: 12 | B16: Строительство автомобильной дороги Подъезд к ИП Коледино в Городском округе Подольск Московской области | C16: 24-53 | D16: 957471.62 | E16: СМР+ПИР | F16: 418987.67 | G16: =F16/D16 -> 0.43759801 | H16: 11211.191 | I16: =H16/F16 -> 0.026757806 | J16: 0 | K16: 11211.191 | L16: =K16/H16 -> 1 | M16: 11211.19 | N16: =M16/D16 -> 0.011709162 | O16: 0 | P16: =O16/D16 -> 0 | Q16: 0 | R16: 0 | S16: 111159.45 | T16: 84890.068 | V16: 64126.924 | Z16: =V16-X16 -> 64126.924 | AA16: 1274254.9 | AB16: 882133.5 | AC16: 1336150.2 | AH16: идет проект-ние | AI16: 0 | AJ16: да | AK16: 46748 | AL16: 46660 | AM16: 46501 | AN16: =D16-M16-Z16-AB16-AD16-AF16 -> 0.00138
A17: 13 | B17: Строительство транспортно- пересадочного узла на железнодорожной станции Лесной городок в Одинцовском городском округе Московской области | C17: 25-106 | D17: 2470626.9 | E17: СМР+ПИР | F17: 741188.06 | G17: =F17/D17 -> 0.3 | H17: 31888.61 | I17: =H17/F17 -> 0.043023642 | J17: 31888.61 | K17: 31888.61 | L17: =K17/H17 -> 1 | M17: 31888.61 | N17: =M17/D17 -> 0.012907093 | O17: 0 | P17: =O17/D17 -> 0 | Q17: 0 | R17: 31888.61 | S17: 826179.92 | T17: 380829.04 | V17: 372229.78 | W17: 967000 | Z17: =V17-X17 -> 372229.78 | AA17: 1612558.7 | AB17: 2066508.5 | AC17: 2255599.7 | AE17: 670635.75 | AH17: идет проект-ние | AI17: 0 | AJ17: нет | AM17: 46746 | AN17: =D17-M17-Z17-AB17-AD17-AF17 -> -0.00012999983
A18: 14 | B18: Строительство боковых проездов а/д М-4 «Дон» в Ленинском городском округе, го Домодедово | C18: 25-73 | D18: 1753364.6 | E18: СМР+ПИР | F18: 526009.4 | G18: =F18/D18 -> 0.3 | H18: 427109.42 | I18: =H18/F18 -> 0.81198059 | J18: 427109.42 | K18: 427109.42 | L18: =K18/H18 -> 1 | M18: 427109.42 | N18: =M18/D18 -> 0.24359418 | O18: 0 | P18: =O18/D18 -> 0 | Q18: 0 | R18: 427109.42 | S18: 153255.31 | T18: 283890.58 | V18: 73255.313 | W18: 180000 | Z18: =V18-X18 -> 73255.313 | AA18: 90000 | AB18: 90000 | AC18: 100000 | AD18: 1162999.9 | AE18: 1490000 | AH18: идет проект-ние | AK18: 47114 | AL18: 46744 | AM18: 47112 | AN18: =D18-M18-Z18-AB18-AD18-AF18 -> -0.00038999994
B19: ДИМ | D19: =SUM(D20:D26) -> 28155094 | F19: =SUM(F20:F26) -> 11521893 | G19: =F19/D19 -> 0.40922941 | H19: =SUM(H20:H26) -> 7241237.3 | I19: =H19/F19 -> 0.62847638 | J19: =SUM(J20:J26) -> 2731721.3 | K19: =SUM(K20:K26) -> 3353747.4 | L19: =K19/H19 -> 0.46314562 | M19: =SUM(M20:M26) -> 10043966 | N19: =M19/D19 -> 0.35673708 | O19: =SUM(O20:O26) -> 6690218.7 | P19: =O19/D19 -> 0.23762018 | Q19: =SUM(Q20:Q26) -> 2323598 | R19: =SUM(R20:R26) -> 3355457.8 | S19: =SUM(S22:S26) -> 1208300.2 | T19: =SUM(T20:T26) -> 5402900.4 | U19: =SUM(U20:U26) -> 71059.086 | V19: =SUM(V20:V26) -> 4518278.9 | W19: =SUM(W20:W26) -> 168000 | X19: =SUM(X20:X26) -> 3239248.1 | Y19: =SUM(Y20:Y26) -> 3239248.1 | Z19: =SUM(Z20:Z26) -> 1279030.8 | AA19: =SUM(AA22:AA26) -> 1999150.4 | AB19: =SUM(AB20:AB26) -> 701982.45 | AC19: =SUM(AC20:AC26) -> 915222.81 | AD19: =SUM(AD20:AD26) -> 2683660.4 | AE19: =SUM(AE20:AE26) -> 3108838.1 | AF19: =SUM(AF20:AF26) -> 13437045 | AG19: =SUM(AG20:AG26) -> 19553430 | AN19: =D19-M19-Z19-AB19-AD19-AF19 -> 9409.4752
A20: 1 | B20: Строительство и реконструкция проезда 4638 в городском округе Котельники Московской области | C20: 24-81 | D20: 765893.46 | E20: СМР+ПИР | F20: 229768.04 | G20: =F20/D20 -> 0.3 | H20: 129000 | I20: =H20/F20 -> 0.56143579 | J20: 119000 | K20: 129000 | L20: =K20/H20 -> 1 | M20: 129000 | N20: =M20/D20 -> 0.16843074 | O20: 0 | P20: =O20/D20 -> 0 | Q20: 0 | R20: 119000 | S20: 113333.33 | T20: 740884.52 | V20: 600834.64 | Z20: =V20-X20 -> 600834.64 | AA20: 523560.12 | AB20: 2718.5075 | AC20: 7133.677 | AH20: 0.01 | AI20: 0.29 | AL20: 46408 | AM20: 46408 | AN20: =D20-M20-Z20-AB20-AD20-AF20 -> 33340.31
A21: 2 | B21: Реконструкция автомобильной дороги Спиридово – «А-104 «Москва – Дмитров – Дубна» – Дмитров – МБК (с реконструкцией мостового перехода через канал им. Москвы) и автомобильной дороги по улице Профессиональная в Дмитровском городском округе Московской области | C21: 46106 | D21: 14764374 | E21: СМР | F21: 7382187.2 | G21: =F21/D21 -> 0.5 | H21: 4996821.2 | I21: =H21/F21 -> 0.67687544 | J21: 2040821.2 | K21: 2028742.1 | L21: =K21/H21 -> 0.40600654 | M21: 4996821.2 | N21: =M21/D21 -> 0.33843772 | O21: 2968079.1 | P21: =O21/D21 -> 0.20102979 | Q21: 1500000 | R21: 2040821.2 | S21: 90000 | T21: 3130000.1 | U21: 44832.304 | V21: 2956000 | X21: 2956000 | Y21: 2956000 | Z21: =V21-X21 -> 0 | AA21: 500000 | AB21: 67000 | AC21: 100000 | AD21: 921000 | AE21: 1000000 | AF21: 8779553.1 | AG21: 14053848 | AH21: 0.08 | AI21: 0.93 | AJ21: да | AK21: 43826 | AL21: 47844 | AM21: 47590 | AN21: =D21-M21-Z21-AB21-AD21-AF21 -> 7.0000067e-05
A22: 3 | B22: Строительство участка автомобильной дороги Мякининское шоссе до автомобильной дороги "Подъездные дороги к Комплексу зданий Административно - общественного Центра Московской области" в Одинцовском городском округе Московской области | C22: 24-88 | D22: 2544160.4 | E22: СМР | F22: 763248.12 | G22: =F22/D22 -> 0.3 | H22: 763248.12 | I22: =H22/F22 -> 1 | J22: 480000 | K22: 683975.87 | L22: =K22/H22 -> 0.8961383 | M22: 763248.12 | N22: =M22/D22 -> 0.3 | O22: 79272.249 | P22: =O22/D22 -> 0.03115851 | Q22: 79272.249 | R22: 480000 | S22: 50000 | T22: 489000 | U22: 26217.132 | V22: 390000 | X22: 283248.12 | Y22: 283248.12 | Z22: =V22-X22 -> 106751.88 | AA22: 1899160.4 | AB22: 80000 | AC22: 88000 | AD22: 1594160.4 | AE22: 1938314.9 | AH22: 0.19 | AI22: 0.68 | AJ22: да | AK22: 47114 | AL22: 46419 | AM22: 46419 | AN22: =D22-M22-Z22-AB22-AD22-AF22 -> 0.0001699999
A23: 4 | B23: Реконструкция участка Мякининского шоссе от автомобильной дороги федерального значения М-9 "Балтия" до МКАД в Одинцовском городском округе Московской области | C23: 24-83 | D23: 135718.92 | E23: СМР | F23: 40715.677 | G23: =F23/D23 -> 0.3 | H23: 40715.677 | I23: =H23/F23 -> 1 | J23: 40715.677 | K23: 37181.564 | L23: =K23/H23 -> 0.91320019 | M23: 44833.223 | N23: =M23/D23 -> 0.33033878 | O23: 7651.659 | P23: =O23/D23 -> 0.056378719 | Q23: 7651.659 | R23: 44833.223 | S23: 67003.246 | T23: 235686 | U23: 9.65 | V23: 70000 | Z23: =V23-X23 -> 70000 | AB23: 44816.524 | AC23: 190848.91 | AE23: 105 | AH23: 0.9 | AI23: 0.8 | AJ23: да | AK23: 47114 | AL23: 45149 | AM23: 46248 | AN23: =D23-M23-Z23-AB23-AD23-AF23 -> -23930.825
A24: 5 | B24: Строительство путепровода через железную дорогу в районе платформы Быково Раменского муниципального района Московской области | C24: 21-47 | D24: 4200892.9 | E24: СМР | F24: 1260267.9 | G24: =F24/D24 -> 0.3 | H24: 1260267.9 | I24: =H24/F24 -> 1 | J24: 0 | K24: 423663.38 | L24: =K24/H24 -> 0.33616931 | M24: 4058879 | N24: =M24/D24 -> 0.96619435 | O24: 3635215.6 | P24: =O24/D24 -> 0.86534356 | Q24: 736674.11 | R24: 619618.88 | S24: 125574.25 | T24: 428514.28 | V24: 142013.9 | Z24: =V24-X24 -> 142013.9 | AH24: 0.98 | AI24: 1 | AJ24: да | AK24: 46383 | AL24: 45580 | AM24: 46265 | AN24: =D24-M24-Z24-AB24-AD24-AF24 -> 0.00029000003
A25: 6 | B25: Строительство подъезда к мкр № 9 от ул. Сосновой в г. Одинцово, Московская область | C25: 46259 | D25: 612447.42 | E25: СМР | F25: 306223.71 | G25: =F25/D25 -> 0.5 | H25: 0 | I25: =H25/F25 -> 0 | J25: 0 | K25: 0 | L25: 0 | M25: 0 | N25: =M25/D25 -> 0 | O25: 0 | P25: =O25/D25 -> 0 | Q25: 0 | R25: 0 | S25: 569447.42 | T25: 200000 | V25: 190000 | Z25: =V25-X25 -> 190000 | AB25: 422447.42 | AC25: 429240.22 | AH25: идет проект-ние | AI25: 0 | AJ25: да | AL25: 46646 | AM25: 46356 | AN25: =D25-M25-Z25-AB25-AD25-AF25 -> 5.0000031e-05
A26: 7 | B26: Строительство путепровода в створе ул. С. Морозова – пр. 30-й Казармы в г. Орехово-Зуево в Орехово-Зуевском городском округе Московской области | C26: 25-57 | D26: 5131606.6 | E26: СМР+ПИР | F26: 1539482 | G26: =F26/D26 -> 0.3 | H26: 51184.458 | I26: =H26/F26 -> 0.033247845 | J26: 51184.459 | K26: 51184.459 | L26: =K26/H26 -> 1 | M26: 51184.459 | N26: =M26/D26 -> 0.0099743535 | O26: 0 | P26: =O26/D26 -> 0 | Q26: 0 | R26: 51184.459 | S26: 396275.3 | T26: 178815.54 | V26: 169430.4 | W26: 168000 | Z26: =V26-X26 -> 169430.4 | AA26: 99990 | AB26: 85000 | AC26: 100000 | AD26: 168500 | AE26: 170418.2 | AF26: 4657491.8 | AG26: 5499581.8 | AH26: идет проект-ние | AL26: 47253 | AM26: 47455 | AN26: =D26-M26-Z26-AB26-AD26-AF26 -> -0.01081
B27: Роуд Групп | D27: =SUM(D28:D33) -> 5882577.9 | F27: =SUM(F28:F33) -> 2245038.3 | G27: =F27/D27 -> 0.38164191 | H27: =SUM(H28:H33) -> 1138170.2 | I27: =H27/F27 -> 0.50697142 | J27: =SUM(J28:J33) -> 466467.16 | K27: =SUM(K28:K33) -> 384563.52 | L27: =K27/H27 -> 0.33787874 | M27: =SUM(M28:M33) -> 2256412.5 | N27: =M27/D27 -> 0.38357546 | O27: =SUM(O28:O33) -> 2010302.3 | P27: =O27/D27 -> 0.34173833 | Q27: =SUM(Q28:Q33) -> 1714222.2 | R27: =SUM(R28:R33) -> 1478718.7 | S27: =SUM(S30:S33) -> 246305.23 | T27: =SUM(T28:T33) -> 1318860.7 | U27: =SUM(U28:U33) -> 20546.569 | V27: =SUM(V28:V33) -> 1173496.4 | W27: =SUM(W28:W33) -> 473000 | X27: =SUM(X28:X33) -> 393102.97 | Y27: =SUM(Y28:Y33) -> 312186.04 | Z27: =SUM(Z28:Z33) -> 780393.47 | AA27: =SUM(AA30:AA33) -> 1043005.5 | AB27: =SUM(AB28:AB33) -> 1509448.3 | AC27: =SUM(AC28:AC33) -> 1722077.8 | AD27: =SUM(AD28:AD33) -> 1336323.5 | AE27: =SUM(AE28:AE33) -> 2343534.3 | AF27: =SUM(AF28:AF33) -> 0 | AG27: =SUM(AG28:AG33) -> 0 | AN27: =D27-M27-Z27-AB27-AD27-AF27 -> 0.00070199929
A28: 1 | B28: Строительство автомобильной дороги регионального значения Волоколамкое шоссе - Нахабино в городском округе Красногорск Московской области. 1 этап | C28: 24-76 | D28: 901195.09 | E28: СМР+ПИР | F28: 270358.53 | G28: =F28/D28 -> 0.3 | H28: 270358.53 | I28: =H28/F28 -> 1 | J28: 95000 | K28: 221366.18 | L28: =K28/H28 -> 0.81878748 | M28: 372518.39 | N28: =M28/D28 -> 0.41336043 | O28: 151152.21 | P28: =O28/D28 -> 0.16772419 | Q28: 0 | R28: 95000 | S28: 90000 | T28: 313424.86 | U28: 15109.809 | V28: 268890.75 | X28: 263385.9 | Y28: 185299.83 | Z28: =V28-X28 -> 5504.8522 | AA28: 1329868.5 | AB28: 523171.85 | AC28: 526123.16 | AE28: 659000 | AH28: 0.4 | AI28: 0 | AJ28: да | AK28: 46748 | AL28: 46748 | AM28: 46748 | AN28: =D28-M28-Z28-AB28-AD28-AF28 -> 0
A29: 2 | B29: Реконструкция автомобильной дороги Калиново – Дракино в городском округе Серпухов Московской области | C29: 46197 | D29: 1842900.9 | E29: СМР+ПИР | F29: 541997.83 | G29: =F29/D29 -> 0.29410036 | H29: 541997.83 | I29: =H29/F29 -> 1 | J29: 255958.24 | K29: 0 | L29: =K29/H29 -> 0 | M29: 1207021.4 | N29: =M29/D29 -> 0.65495731 | O29: 1345474.8 | P29: =O29/D29 -> 0.73008524 | Q29: 1207021.4 | R29: 920981.86 | S29: 576901.62 | T29: 534463.81 | U29: 436.76 | V29: 520000 | Z29: =V29-X29 -> 520000 | AB29: 115879.49 | AC29: 236000 | AH29: 0.652 | AI29: 0.99 | AJ29: да | AK29: 46748 | AL29: 46017 | AM29: 46115 | AN29: =D29-M29-Z29-AB29-AD29-AF29 -> -1.3096724e-10
A30: 3 | B30: Строительство подъезда к ИП «Новопетровское» в городском округе Истра Московской области. Этап 1 | C30: 46227 | D30: 542045.64 | E30: СМР+ПИР | F30: 162613.69 | G30: =F30/D30 -> 0.3 | H30: 162616.54 | I30: =H30/F30 -> 1.0000175 | J30: 78197.782 | K30: 0 | L30: =K30/H30 -> 0 | M30: 513675.36 | N30: =M30/D30 -> 0.94766071 | O30: 513675.36 | P30: =O30/D30 -> 0.94766071 | Q30: 507200.79 | R30: 426425.74 | S30: 17998.491 | T30: 39000 | U30: 5000 | V30: 31201.137 | X30: 2830.8555 | Z30: =V30-X30 -> 28370.281 | AC30: 78500.468 | AH30: 0.99 | AI30: 0.86 | AJ30: да | AK30: 46748 | AL30: 46137 | AM30: 46137 | AN30: =D30-M30-Z30-AB30-AD30-AF30 -> -0.00021000004
A31: 4 | B31: Строительство транспортной развязки в одном уровне на пересечении автомобильных дорог М-9 «Балтия» и «Аносино-Покровское» в городском округе Истра Московской области | C31: 25-60 | D31: 942039.37 | E31: СМР+ПИР | F31: 471019.68 | G31: =F31/D31 -> 0.5 | H31: 125424.37 | I31: =H31/F31 -> 0.26628266 | J31: 14424.373 | K31: 125424.37 | L31: =K31/H31 -> 1 | M31: 125424.37 | N31: =M31/D31 -> 0.13314133 | O31: 0 | P31: =O31/D31 -> 0 | Q31: 0 | R31: 14424.373 | S31: 108424.3 | T31: 245168.24 | V31: 213993.15 | W31: 205000 | X31: 111000 | Y31: 111000 | Z31: =V31-X31 -> 102993.15 | AA31: 819189.92 | AB31: 713621.85 | AC31: 719679.06 | AH31: идет проект-ние | AI31: 0 | AJ31: да | AK31: 46748 | AL31: 46507 | AM31: 46707 | AN31: =D31-M31-Z31-AB31-AD31-AF31 -> 1.1641532e-10
A32: 5 | B32: Строительство обхода СНТ «Кино» в районе д. Ламоново в муниципальном округе Истра Московской области | C32: 25-75 | D32: 140749.48 | E32: СМР+ПИР | F32: 42224.843 | G32: =F32/D32 -> 0.29999999 | H32: 3224.843 | I32: =H32/F32 -> 0.07637312 | J32: 3224.844 | K32: 3224.844 | L32: =K32/H32 -> 1.0000003 | M32: 3224.8438 | N32: =M32/D32 -> 0.022911941 | O32: 0 | P32: =O32/D32 -> 0 | Q32: 0 | R32: 3224.844 | S32: 13709.075 | T32: 70000 | V32: 60749.479 | Z32: =V32-X32 -> 60749.479 | AA32: 123815.56 | AB32: 76775.156 | AC32: 76775.156 | AH32: идет проект-ние | AI32: 0 | AJ32: да | AL32: 46694 | AM32: 46707 | AN32: =D32-M32-Z32-AB32-AD32-AF32 -> 1.9999716e-06
A33: 6 | B33: Строительство автомобильной дороги А-103 «Щелковское шоссе» - Черноголовка-МБК в го Черноголовка 1 этап | C33: 25-67 | D33: 1513647.4 | E33: СМР+ПИР | F33: 756823.69 | G33: =F33/D33 -> 0.5 | H33: 34548.131 | I33: =H33/F33 -> 0.04564885 | J33: 19661.918 | K33: 34548.131 | L33: =K33/H33 -> 1 | M33: 34548.131 | N33: =M33/D33 -> 0.022824425 | O33: 0 | P33: =O33/D33 -> 0 | Q33: 0 | R33: 18661.918 | S33: 106173.36 | T33: 116803.78 | V33: 78661.918 | W33: 268000 | X33: 15886.214 | Y33: 15886.214 | Z33: =V33-X33 -> 62775.704 | AA33: 100000 | AB33: 80000 | AC33: 85000 | AD33: 1336323.5 | AE33: 1684534.3 | AH33: идет проект-ние | AK33: 47114 | AL33: 46744 | AM33: 47088 | AN33: =D33-M33-Z33-AB33-AD33-AF33 -> 0.00090999994
B34: СИБАГРО | D34: =SUM(D35:D36) -> 18443317 | F34: =SUM(F35:F36) -> 6085839.2 | G34: =F34/D34 -> 0.32997531 | H34: =SUM(H35:H36) -> 4898579.6 | I34: =H34/F34 -> 0.8049144 | J34: =SUM(J35:J36) -> 4053318.4 | K34: =SUM(K35:K36) -> 282294.54 | L34: =K34/H34 -> 0.057627835 | M34: =SUM(M35:M36) -> 17825341 | N34: =M34/D34 -> 0.96649325 | O34: =SUM(O35:O36) -> 17543900 | P34: =O34/D34 -> 0.95123345 | Q34: =SUM(Q35:Q36) -> 2207901.6 | R34: =SUM(R35:R36) -> 1098340.7 | S34: =SUM(S35:S36) -> 567665.18 | T34: =SUM(T35:T36) -> 950687.18 | U34: =SUM(U35:U36) -> 0 | V34: =SUM(V35:V36) -> 601465.95 | W34: =SUM(W35:W36) -> 0 | X34: =SUM(X35:X36) -> 2557.2004 | ... AG34: =SUM(AG35:AG36) -> 0 | AN34: =D34-M34-Z34-AB34-AD34-AF34 -> 19066.824
A35: 1 | B35: Строительство подъездов к лицею им. В.И. Долгих в городском округе Истра Московской области | C35: 22-72 | D35: 3262915.1 | E35: СМР+ПИР | F35: 1531718.7 | G35: =F35/D35 -> 0.46943261 | H35: 845261.21 | I35: =H35/F35 -> 0.55183839 | J35: 0 | K35: 0 | L35: =K35/H35 -> 0 | M35: 3043241 | N35: =M35/D35 -> 0.93267551 | O35: 3044094.2 | P35: =O35/D35 -> 0.93293699 | Q35: 810621.06 | R35: 525632.2 | S35: 188430.53 | T35: 336300 | V35: 222231.3 | X35: 2557.2004 | Z35: =V35-X35 -> 219674.1 | AC35: 133522.57 | AH35: 0.97 | AI35: 1 | AJ35: да | AK35: 46748 | AL35: 45170 | AM35: 46052 | AN35: =D35-M35-Z35-AB35-AD35-AF35 -> 4.0745363e-10
A36: 2 | B36: Строительство автомобильной дороги А-104 «Москва-Дмитров- Дубна» - Рогачевское шоссе» (северный обход г.Лобни) | C36: 46316 | D36: 15180402 | E36: СМР | F36: 4554120.5 | G36: =F36/D36 -> 0.3 | H36: 4053318.4 | I36: =H36/F36 -> 0.89003319 | J36: 4053318.4 | K36: 282294.54 | L36: =K36/H36 -> 0.06964529 | M36: 14782100 | N36: =M36/D36 -> 0.97376213 | O36: 14499806 | P36: =O36/D36 -> 0.95516614 | Q36: 1397280.6 | R36: 572708.49 | S36: 379234.65 | T36: 614387.18 | V36: 379234.65 | Z36: =V36-X36 -> 379234.65 | AH36: 0.98 | AI36: 1 | AJ36: да | AK36: 46383 | AL36: 44915 | AM36: 46157 | AN36: =D36-M36-Z36-AB36-AD36-AF36 -> 19066.824
B37: СТРОЙКОМ | D37: =SUM(D38:D39) -> 3951124.7 | F37: =SUM(F38:F39) -> 1185337.4 | G37: =F37/D37 -> 0.3 | H37: =SUM(H38:H39) -> 1175636.8 | I37: =H37/F37 -> 0.99181617 | J37: =SUM(J38:J39) -> 0 | K37: =SUM(K38:K39) -> 40039.59 | L37: =K37/H37 -> 0.034057789 | M37: =SUM(M38:M39) -> 3903059.9 | N37: =M37/D37 -> 0.98783516 | O37: =SUM(O38:O39) -> 3903059.9 | P37: =O37/D37 -> 0.98783516 | Q37: =SUM(Q38:Q39) -> 1719900.9 | R37: =SUM(R38:R39) -> 1203915.3 | S37: =SUM(S38:S39) -> 51076.039 | T37: =SUM(T38:T39) -> 354164.75 | U37: =SUM(U38:U39) -> 0 | V37: =SUM(V38:V39) -> 108700.75 | W37: =SUM(W38:W39) -> 212000 | X37: =SUM(X38:X39) -> 60635.947 | ... AG37: =SUM(AG38:AG39) -> 0 | AN37: =D37-M37-Z37-AB37-AD37-AF37 -> -0.00064000025
A38: 1 | B38: Строительство подъездов к лицею им. В.И. Долгих в городском округе Истра Московской области | C38: 46166 | D38: 3770638.4 | E38: СМР | F38: 1131191.5 | G38: =F38/D38 -> 0.3 | H38: 1131191.5 | I38: =H38/F38 -> 1 | J38: 0 | K38: 40039.59 | L38: =K38/H38 -> 0.035395942 | M38: 3723024.2 | N38: =M38/D38 -> 0.98737237 | O38: 3723024.2 | P38: =O38/D38 -> 0.98737237 | Q38: 1583835.4 | R38: 1108684.8 | S38: 35852.107 | T38: 336300 | V38: 93425.711 | X38: 45811.476 | Z38: =V38-X38 -> 47614.235 | AC38: 133522.57 | AH38: 0.97 | AI38: 0.99 | AJ38: да | AK38: 46748 | AL38: 45170 | AM38: 46302 | AN38: =D38-M38-Z38-AB38-AD38-AF38 -> -0.00029000006
A39: 2 | B39: Строительство автомобильной дороги «Хлебниково-Рогачево»-«Шереметьево-1-Шереметьево-2» в городских округах Химки, Мытищи, Лобня Московской области. Этап 2 | C39: 46136 | D39: 180486.26 | E39: СМР+ПИР | F39: 54145.878 | G39: =F39/D39 -> 0.3 | H39: 44445.283 | I39: =H39/F39 -> 0.82084334 | J39: 0 | K39: 0 | L39: =K39/H39 -> 0 | M39: 180035.69 | N39: =M39/D39 -> 0.9975036 | O39: 180035.69 | P39: =O39/D39 -> 0.9975036 | Q39: 136065.48 | R39: 95230.501 | S39: 15223.932 | T39: 17864.752 | V39: 15275.037 | W39: 212000 | X39: 14824.47 | Z39: =V39-X39 -> 450.56674 | AC39: 212000 | AH39: 0.98 | AJ39: да | AK39: 46116 | AL39: 46116 | AM39: 46116 | AN39: =D39-M39-Z39-AB39-AD39-AF39 -> -0.00035000001
B40: АРКС+МИСК | D40: =D41+D49 -> 57138138 | F40: =F41+F49 -> 22719415 | G40: =F40/D40 -> 0.3976226 | H40: =H41+H49 -> 20823360 | I40: =H40/F40 -> 0.91654472 | J40: =J41+J49 -> 4439433.4 | K40: =K41+K49 -> 14644634 | L40: =K40/H40 -> 0.70327909 | M40: =M41+M49 -> 30857232 | N40: =M40/D40 -> 0.54004616 | O40: =O41+O49 -> 16212598 | P40: =O40/D40 -> 0.2837439 | Q40: =Q41+Q49 -> 8440514.5 | R40: =R41+R49 -> 9441521 | T40: =T41+T49 -> 7294120.4 | U40: =U41+U49 -> 531646.48 | V40: =V41+V49 -> 6221164.9 | W40: =W41+W49 -> 180000 | X40: =X41+X49 -> 2493507.5 | Y40: =Y41+Y49 -> 2466744.4 | Z40: =Z41+Z49 -> 3727657.4 | AB40: =AB41+AB49 -> 4195861.7 | AC40: =AC41+AC49 -> 4507670 | AD40: =AD41+AD49 -> 7216437.4 | AE40: =AE41+AE49 -> 10387625 | AF40: =AF41+AF49 -> 10965948 | AG40: =AG41+AG49 -> 13444040 | AN40: =D40-M40-Z40-AB40-AD40-AF40 -> 175002.2
B41: АРКС | D41: =SUM(D42:D48) -> 30212486 | F41: =SUM(F42:F48) -> 12393381 | G41: =F41/D41 -> 0.41020726 | H41: =SUM(H42:H48) -> 12305247 | I41: =H41/F41 -> 0.99288861 | J41: =SUM(J42:J48) -> 3589486.4 | K41: =SUM(K42:K48) -> 7273824.5 | L41: =K41/H41 -> 0.59111568 | M41: =SUM(M42:M48) -> 20926377 | N41: =M41/D41 -> 0.69264002 | O41: =SUM(O42:O48) -> 13652552 | P41: =O41/D41 -> 0.45188444 | Q41: =SUM(Q42:Q48) -> 7850235.4 | R41: =SUM(R42:R48) -> 8291940.6 | S41: =SUM(S44:S48) -> 1256418 | T41: =SUM(T42:T48) -> 2784564.4 | U41: =SUM(U42:U48) -> 230939.75 | V41: =SUM(V42:V48) -> 2243643 | W41: =SUM(W42:W48) -> 0 | X41: =SUM(X42:X48) -> 0 | Y41: =SUM(Y42:Y48) -> 0 | Z41: =SUM(Z42:Z48) -> 2243643 | AA41: =SUM(AA44:AA48) -> 1016247.1 | AB41: =SUM(AB42:AB48) -> 1823734.6 | AC41: =SUM(AC42:AC48) -> 1999065.6 | AD41: =SUM(AD42:AD48) -> 738325.29 | AE41: =SUM(AE42:AE48) -> 1636153.1 | AF41: =SUM(AF42:AF48) -> 4445094.5 | AG41: =SUM(AG42:AG48) -> 5454325.6 | AN41: =D41-M41-Z41-AB41-AD41-AF41 -> 35311.87
...

Sheet СМР
A1: Объекты строительства
S2: =S6+S113 -> 1.7046656e+08 | T2: =T6+T113 -> 54007714 | U2: =T2/S2 -> 0.31682293 | V2: =V6+V113 -> 45669502 | W2: =V2/S2 -> 0.26790886 | X2: =X6+X113 -> 15920497 | Y2: =X2/S2 -> 0.093393666 | Z2: =Z6+Z113 -> 60734386 | AA2: =AA6+AA113 -> 14282619 | AB2: =AB6+AB113 -> 8338212.2 | AC2: =AB2/S2 -> 0.048914065 | AD2: =AD6+AD113 -> 8089901.3 | AE2: =AE6+AE113 -> 3536305.9 | AF2: =AE2/S2 -> 0.020744866 | AG2: =AG6+AG113 -> 154886.11 | AH2: =AG2/S2 -> 0.00090860115 | AN2: =AN6+AN113 -> 4.570364e+08 | AO2: =AO6+AO113 -> 42623769 | AP2: =AP6+AP113 -> 32711658 | AQ2: =AQ6+AQ113 -> 42308446 | AR2: =AR6+AR113 -> 57053448 | AS2: =AS6+AS113 -> 46897339 | AT2: =AT6+AT113 -> 74778844 | AU2: =AU6+AU113 -> 1.8523164e+08 | AV2: =AV6+AV113 -> 34230190
A3: № п/п | B3: № п/п | C3: Мероприятие | D3: ОМСУ | E3: Объект | F3: Мощность/ прирост мощности объекта дорожного хозяйства | H3: Контракт дата заключения | I3: Контракт № | J3: Подрядчик | K3: Строительная готовность 22.05., % | L3: Строительная готовность 29.05., % | M3: Динамика за неделю, % | N3: Кол-во рабочих | O3: Кол-во техники | P3: МОГЭ | Q3: Статус ДПТ | R3: ЗУ | S3: Цена контракта, тыс.руб. | T3: Оплачено всего, тыс.руб. | U3: Оплачено всего, % | V3: Аванс, тыс.руб. | W3: Аванс, % | X3: Принято, тыс.руб. | Y3: Принято,% | Z3: Аванс по ГК, тыс.руб. | AA3: Остаток аванса к оплате, тыс.руб. | AB3: Оплата за вычетом аванса, тыс. руб. | AC3: Оплата за вычетом аванса, % | AD3: Оплачено 2026, тыс руб. | AE3: Аванс 2026, тыс.руб. | AF3: Аванс 2026, % | AG3: Оплата за вычетом аванса 2026, тыс.руб. | AH3: Оплата за вычетом аванса 2026, % | AI3: Кассовый разрыв | AJ3: Срок действия ГК | AK3: Источники финансирования | AL3: Сроки по ГП (ввод) | AM3: Открытие по ГП | AN3: Стоимость объекта | AO3: Профинансиро- вано на 01.01.2025 (тыс. руб.) | AP3: 2025 | AQ3: 2026 | AR3: 2027 | AS3: 2028 | AT3: 2029 | AU3: Остаток сметной стоимости до ввода | AV3: Остаток лимитов 2026
F5: км | G5: пог. м
S6: =S9+S15+S36+S42+S58+S76+S87 -> 1.7046656e+08 | T6: =T9+T15+T36+T42+T58+T76+T87 -> 54007714 | U6: =T6/S6 -> 0.31682293 | V6: =V9+V15+V36+V42+V58+V76+V87 -> 45669502 | W6: =V6/S6 -> 0.26790886 | X6: =X9+X15+X36+X42+X58+X76+X87 -> 15920497 | Y6: =X6/S6 -> 0.093393666 | Z6: =Z9+Z15+Z36+Z42+Z58+Z76+Z87 -> 60734386 | AA6: =AA9+AA15+AA36+AA42+AA58+AA76+AA87 -> 14282619 | AB6: =AB9+AB15+AB36+AB42+AB58+AB76+AB87 -> 8338212.2 | AC6: =AB6/S6 -> 0.048914065 | AD6: =AD9+AD15+AD36+AD42+AD58+AD76+AD87 -> 8089901.3 | AE6: =AE9+AE15+AE36+AE42+AE58+AE76+AE87 -> 3536305.9 | AF6: =AE6/S6 -> 0.020744866 | AG6: =AG9+AG15+AG36+AG42+AG58+AG76+AG87 -> 154886.11 | AH6: =AG6/S6 -> 0.00090860115 | AN6: =AN9+AN15+AN36+AN42+AN58+AN76+AN87 -> 2.6715758e+08 | AO6: =AO9+AO15+AO36+AO42+AO58+AO76+AO87 -> 35459573 | AP6: =AP9+AP15+AP36+AP42+AP58+AP76+AP87 -> 32542667 | AQ6: =AQ9+AQ15+AQ36+AQ42+AQ58+AQ76+AQ87 -> 32757640 | AR6: =AR9+AR15+AR36+AR42+AR58+AR76+AR87 -> 44943260 | AS6: =AS9+AS15+AS36+AS42+AS58+AS76+AS87 -> 44971161 | AT6: =AT9+AT15+AT36+AT42+AT58+AT76+AT87 -> 72442814 | AU6: =AU9+AU15+AU36+AU42+AU58+AU76+AU87 -> -0.00039999932 | AV6: =AV9+AV15+AV36+AV42+AV58+AV76+AV87 -> 24679385
A7: ОБЪЕКТЫ ФБ/ИБК/КИК 2026
S8: =S9+S15 -> 22219462 | T8: =T9+T15 -> 9597035.1 | U8: =T8/S8 -> 0.43192022 | V8: =V9+V15 -> 7889046.7 | W8: =V8/S8 -> 0.35505119 | X8: =X9+X15 -> 2991961.8 | Y8: =X8/S8 -> 0.134655 | AB8: =AB9+AB15 -> 1707988.5 | AD8: =AD9+AD15 -> 1207518 | AN8: =AN9+AN15 -> 37313426 | AO8: =AO9+AO15 -> 13263747 | AP8: =AP9+AP15 -> 5060206 | AQ8: =AQ9+AQ15 -> 9679816 | AR8: =AR9+AR15 -> 6966104.4 | AS8: =AS9+AS15 -> 2343551.9 | AT8: =AT9+AT15 -> 0 | AU8: =AU9+AU15 -> 0 | AV8: =AV9+AV15 -> 8483944.1
S9: =SUM(S10:S13) -> 11188649 | T9: =SUM(T10:T13) -> 6033619.1 | U9: =T9/S9 -> 0.53926251 | V9: =SUM(V10:V13) -> 5135584.6 | W9: =V9/S9 -> 0.45899952 | X9: =SUM(X10:X13) -> 1808893.5 | Y9: =X9/S9 -> 0.1616722 | Z9: =SUM(Z10:Z13) -> 6286713 | AA9: =SUM(AA10:AA13) -> 1151128.4 | AB9: =SUM(AB10:AB13) -> 898034.46 | AC9: =AB9/S9 -> 0.080262992 | AD9: =SUM(AD10:AD13) -> 0 | AE9: =SUM(AE10:AE13) -> 0 | AF9: =AE9/S9 -> 0 | AG9: =SUM(AG10:AG13) -> 0 | AH9: =AG9/S9 -> 0 | AN9: =SUM(AN10:AN13) -> 20799485 | AO9: =SUM(AO10:AO13) -> 12595091 | AP9: =SUM(AP10:AP13) -> 2412305.9 | AQ9: =SUM(AQ10:AQ13) -> 4537023.2 | AR9: =SUM(AR10:AR13) -> 1182865.3 | AS9: =SUM(AS10:AS13) -> 72200 | AT9: =SUM(AT10:AT13) -> 0 | AU9: =SUM(AU10:AU13) -> 0 | AV9: =SUM(AV10:AV13) -> 4537023.2
A10: 1 | B10: 1 | C10: 01.10 | D10: Лобня | E10: Реконструкция автомобильной дороги «А-104 «Москва - Дмитров - Дубна» - Поведники» на участке км 0 - км 2,74 (Афанасовское шоссе) КИК | F10: 4.00154 | H10: 44872 | I10: № 1/2022-77 | J10: ООО "ПФ "ВИС" | K10: 0.86 | L10: 0.86 | M10: =L10-K10 -> 0 | N10: 24 | O10: 11 | P10: 45894 | Q10: Утверждено | R10: 1 | S10: 3548732.6 | T10: =2732000.55157-3098.60949 -> 2728901.9 | U10: =T10/S10 -> 0.76897932 | V10: 2471263 | W10: =V10/S10 -> 0.69637905 | X10: 634328.91 | Y10: =X10/S10 -> 0.17874802 | Z10: 2484112.8 | AA10: =Z10-V10 -> 12849.785 | AB10: =T10-V10 -> 257638.93 | AC10: =AB10/S10 -> 0.072600266 | AD10: 0 | AE10: 0 | AF10: =AE10/S10 -> 0 | AG10: 0 | AH10: =AG10/U10 -> 0 | AI10: =U10-L10 -> -0.091020685 | AJ10: 11.01.2026 | AK10: ДФ МО | AL10: 02.07.2018- 27.12.2028 | AM10: 46356 | AN10: 8728017.5 | AO10: 6972779.2 | AP10: 715721.03 | AQ10: 899966.22 | AR10: 97432.053 | AS10: 42119 | AT10: 0 | AU10: 0 | AV10: =AQ10-AD10 -> 899966.22 | AW10: https://zakupki.gov.ru/epz/contract/contractCard/common-info.html?reestrNumber=2502415352722000101 | AX10: 2502415352722000101 пи
A11: 2 | B11: 2 | C11: 01.10 | D11: Наро-Фоминский | E11: Строительство путепровода на автомобильной дороге «г.п. Апрелевка, ул. Апрелевская» у пл. Апрелевка, Наро-Фоминский го ФБ | F11: 2.07595 | G11: 273 | H11: 46003 | I11: № 1/2025-127 | J11: АО "СТРОЙТРАНСГАЗ" | K11: 0.45 | L11: 0.45 | M11: =L11-K11 -> 0 | N11: 23 | O11: 4 | P11: декабрь 2020. Выполняется корректировка, план получения - 2 кв.2026 | Q11: Утверждено | R11: 0.97 | S11: 3312365.1 | T11: 861244.23 | U11: =T11/S11 -> 0.26000885 | V11: 861244.23 | W11: =V11/S11 -> 0.26000885 | X11: 0 | Y11: 0 | Z11: 1656182.6 | AA11: =Z11-V11 -> 794938.32 | AB11: =T11-V11 -> 0 | AC11: =AB11/S11 -> 0 | AD11: 0 | AE11: 0 | AF11: =AE11/S11 -> 0 | AG11: 0 | AH11: =AG11/U11 -> 0 | AI11: =U11-L11 -> -0.18999115 | AJ11: 15.04.2027 | AK11: ФБ ДФ МО | AL11: 30.07.2019- 31.12.2027 | AM11: 46356 | AN11: 5343237.1 | AO11: 1846515.1 | AP11: 890339.68 | AQ11: 2112884.3 | AR11: 493498.05 | AS11: 0 | AT11: 0 | AU11: 0 | AV11: =AQ11-AD11 -> 2112884.3 | AW11: https://zakupki.gov.ru/epz/contract/contractCard/common-info.html?reestrNumber=2502415352725000168 | AX11: 2502415352725000168 пи
A12: 3 | B12: 3 | C12: 01.10 | D12: Красногорск | E12: Строительство путепровода на 0+820 км автодороги ул. Опалиха, г. Красногорск, мкр. Опалиха ФБ | F12: 1.97469 | G12: 136.76 | H12: 45947 | I12: № 1/2025-95 | J12: АО "СТРОЙТРАНСГАЗ" | K12: 0.45 | L12: 0.45 | M12: =L12-K12 -> 0 | N12: 40 | O12: 7 | P12: 43763 | Q12: Утверждено | R12: 1 | S12: 1704671.5 | T12: 569565.68 | U12: =T12/S12 -> 0.3341205 | V12: 569565.68 | W12: =V12/S12 -> 0.3341205 | X12: 0 | Y12: =X12/S12 -> 0 | Z12: 852335.73 | AA12: =Z12-V12 -> 282770.05 | AB12: =T12-V12 -> 0 | AC12: =AB12/S12 -> 0 | AD12: 0 | AE12: 0 | AF12: =AE12/S12 -> 0 | AG12: 0 | AH12: =AG12/U12 -> 0 | AI12: =U12-L12 -> -0.1158795 | AJ12: 18.01.2027 | AK12: ФБ ДФ МО | AL12: 14.05.2019- 31.12.2027 | AM12: 46356 | AN12: 3979181 | AO12: 2037580.4 | AP12: 583427.89 | AQ12: 1154172.7 | AR12: 204000 | AS12: 0 | AT12: 0 | AU12: 0 | AV12: =AQ12-AD12 -> 1154172.7 | AW12: https://zakupki.gov.ru/epz/contract/contractCard/common-info.html?reestrNumber=2502415352725000137 | AX12: 2502415352725000137 пи
A13: 4 | B13: 4 | C13: 01.10 | D13: Мытищи | E13: Реконструкция автомобильной дороги Пироговское шоссе на участке от автомобильной дороги Волковское шоссе до автомобильной дороги «Виноградово - Болтино - Тарасовка» в городском округе Мытищи Московской области ИБК | F13: 2.15463 | G13: 79.2 | H13: 44537 | I13: № 1/2021-41 | J13: ООО "ИФСК "АРКС" | K13: 0.85 | L13: 0.85 | M13: =L13-K13 -> 0 | N13: 10 | O13: 2 | P13: 44741 | Q13: Утверждено | R13: 1 | S13: 2622880.2 | T13: 1873907.3 | U13: =T13/S13 -> 0.71444639 | V13: 1233511.7 | W13: =V13/S13 -> 0.47028901 | X13: 1174564.6 | Y13: =X13/S13 -> 0.44781482 | Z13: 1294081.9 | AA13: =Z13-V13 -> 60570.209 | AB13: =T13-V13 -> 640395.54 | AC13: =AB13/S13 -> 0.24415738 | AD13: 0 | AE13: 0 | AF13: =AE13/S13 -> 0 | AG13: 0 | AH13: =AG13/U13 -> 0 | AI13: =U13-L13 -> -0.13555361 | AJ13: 46418 | AK13: ДФ МО | AL13: 07.12.2021- 27.12.2028 | AM13: 46371 | AN13: 2749049.8 | AO13: 1738216.3 | AP13: 222817.32 | AQ13: 370000 | AR13: 387935.19 | AS13: 30081 | AT13: 0 | AU13: 0 | AV13: =AQ13-AD13 -> 370000 | AW13: https://zakupki.gov.ru/epz/contract/contractCard/common-info.html?reestrNumber=2502415352721000085 | AX13: 2502415352721000085 пи
A14: 2026
S15: =SUM(S16:S33) -> 11030813 | T15: =SUM(T16:T33) -> 3563416 | U15: =T15/S15 -> 0.32304201 | V15: =SUM(V16:V33) -> 2753462 | W15: =V15/S15 -> 0.24961551 | X15: =SUM(X16:X33) -> 1183068.3 | Y15: =X15/S15 -> 0.10725123 | Z15: =SUM(Z16:Z33) -> 4276044.6 | AA15: =SUM(AA16:AA33) -> 1522582.6 | AB15: =SUM(AB16:AB33) -> 809954.01 | AC15: =AB15/S15 -> 0.073426501 | AD15: =SUM(AD16:AD33) -> 1207518 | AE15: =SUM(AE16:AE33) -> 539648.18 | AF15: =AE15/S15 -> 0.048921886 | AG15: =SUM(AG16:AG33) -> 154886.11 | AH15: =AG15/S15 -> 0.014041223 | AN15: =SUM(AN16:AN33) -> 16513940 | AO15: =SUM(AO16:AO33) -> 668656.44 | AP15: =SUM(AP16:AP33) -> 2647900 | AQ15: =SUM(AQ16:AQ33) -> 5142792.8 | AR15: =SUM(AR16:AR33) -> 5783239.1 | AS15: =SUM(AS16:AS33) -> 2271351.9 | AT15: =SUM(AT16:AT33) -> 0 | AU15: =SUM(AU16:AU33) -> 0 | AV15: =SUM(AV16:AV33) -> 3946920.8
